Workbook

Sheet Dashboard
B1: RUBAN | E1: Premium Fashion D2C Brand | W1: Showing: Year 5
E2: 5-Year Financial Model | W2: FY 2028-29
B4: Revenue | E4: Gross Profit | H4: OPEX | K4: EBITDA | N4: Customers | Q4: Churn | T4: CAC | W4: LTV
B5: ₹85.0 Cr | E5: ₹49.3 Cr | H5: ₹21.8 Cr | K5: ₹27.5 Cr | N5: 120,000 | Q5: 20% | T5: ₹480 | W5: ₹14,500
B6: +77% YoY | E6: +80% YoY | H6: 26% of Revenue | K6: 18% Margin | N6: +67% YoY | Q6: Improving ↓ | T6: -20% YoY | W6: +21% YoY
B8: Revenue Trend | K8: Revenue Breakup | Q8: Profitability Ratios
Q16: Deal Snapshot — Series B
Q17: Funding Ask | T17: Post Valuation | W17: Stake
Q18: ₹50 Cr | T18: ₹300 Cr | W18: 16.7%
Q19: Seed MOIC | U19: 24.2x
Q20: Series A MOIC | U20: 4.5x
Q21: Series B MOIC | U21: 2.3x
Q22: Blended IRR | U22: 68%
B24: Customer Funnel | H24: Customer Growth by Channel | R24: Use of Funds
R31: Shareholding — Y5
B40: Cash Balance | E40: EBITDA Margin | H40: Revenue CAGR | K40: LTV/CAC | N40: Payback | Q40: Net Margin | T40: Exit Val. | W40: Seed MOIC
B41: ₹35.8 Cr | E41: 18% | H41: 144% | K41: 30.2x | N41: 3 months | Q41: 28.7% | T41: ₹680 Cr | W41: 24.2x

Sheet Assumptions
A1: RUBAN — Model Assumptions
B2: Year 1 | C2: Year 2 | D2: Year 3 | E2: Year 4 | F2: Year 5 | G2: Notes
A3: Revenue Drivers
A4: Website — Active Customers | B4: 1800 | C4: 5500 | D4: 14000 | E4: 25200 | F4: 39600 | G4: Cumulative
A5: Retail — Active Customers | B5: 0 | C5: 2000 | D5: 7000 | E5: 18000 | F5: 33600 | G5: Opens Y2
A6: Marketplace — Active Customers | B6: 1400 | C6: 5000 | D6: 14000 | E6: 28800 | F6: 46800
A7: Total Active Customers | B7: =SUM(B4:B6) | C7: =SUM(C4:C6) | D7: =SUM(D4:D6) | E7: =SUM(E4:E6) | F7: =SUM(F4:F6) | G7: =Sum of channels
A9: Website — New Customers | B9: 1800 | C9: 4500 | D9: 10500 | E9: 15400 | F9: 21600
A10: Retail — New Customers | B10: 0 | C10: 2000 | D10: 6000 | E10: 14000 | F10: 21600
A11: Marketplace — New Customers | B11: 1400 | C11: 4200 | D11: 11000 | E11: 19800 | F11: 28800
A13: Website — AOV (₹) | B13: 3000 | C13: 3300 | D13: 3600 | E13: 3800 | F13: 4000
A14: Retail — AOV (₹) | B14: 0 | C14: 3800 | D14: 4200 | E14: 4500 | F14: 4800
A15: Marketplace — AOV (₹) | B15: 2500 | C15: 2800 | D15: 3000 | E15: 3200 | F15: 3400
A16: Blended AOV (₹) | B16: 2800 | C16: 3100 | D16: 3400 | E16: 3600 | F16: 3800 | G16: Weighted average
A18: Website — Orders/Cust/Year | B18: 1.8 | C18: 2 | D18: 2.2 | E18: 2.4 | F18: 2.5
A19: Retail — Orders/Cust/Year | B19: 0 | C19: 1.5 | D19: 1.8 | E19: 2 | F19: 2.2
A20: Marketplace — Orders/Cust/Year | B20: 1.5 | C20: 1.8 | D20: 2 | E20: 2.2 | F20: 2.3
A22: Cost Structure
A23: Website — COGS % | B23: 0.48 | C23: 0.46 | D23: 0.44 | E23: 0.43 | F23: 0.42
A24: Retail — COGS % | B24: 0 | C24: 0.5 | D24: 0.47 | E24: 0.45 | F24: 0.43
A25: Marketplace — COGS % | B25: 0.48 | C25: 0.46 | D25: 0.44 | E25: 0.43 | F25: 0.42
A26: Gross Margin % (Blended) | B26: 0.52 | C26: 0.54 | D26: 0.56 | E26: 0.57 | F26: 0.58 | G26: Target
A28: Return Rate — Website | B28: 0.08 | C28: 0.08 | D28: 0.07 | E28: 0.07 | F28: 0.06
A29: Return Rate — Retail | B29: 0 | C29: 0.03 | D29: 0.03 | E29: 0.03 | F29: 0.03
A30: Return Rate — Marketplace | B30: 0.1 | C30: 0.1 | D30: 0.09 | E30: 0.09 | F30: 0.08
A31: Marketplace Commission % | B31: 0.15 | C31: 0.14 | D31: 0.13 | E31: 0.12 | F31: 0.11
A33: Operating Expenses (₹ Cr)
A34: Marketing & Advertising | B34: 0.96 | C34: 2.13 | D34: 3.52 | E34: 5.28 | F34: 7.65
A35: Employee Costs | B35: 0.55 | C35: 1.2 | D35: 2.2 | E35: 3.84 | F35: 5.95
A36: Technology & Platform | B36: 0.24 | C36: 0.43 | D36: 0.66 | E36: 0.96 | F36: 1.28
A37: Rent & Utilities | B37: 0 | C37: 0.36 | D37: 0.88 | E37: 1.44 | F37: 1.87
A38: Logistics & Fulfillment | B38: 0.19 | C38: 0.6 | D38: 1.32 | E38: 2.4 | F38: 3.83
A39: Other G&A | B39: 0.14 | C39: 0.34 | D39: 0.66 | E39: 0.96 | F39: 1.19
A40: Total OPEX | B40: =SUM(B34:B39) | C40: =SUM(C34:C39) | D40: =SUM(D34:D39) | E40: =SUM(E34:E39) | F40: =SUM(F34:F39)
A42: Working Capital Assumptions (Days)
A43: Inventory Days | B43: 30 | C43: 35 | D43: 35 | E43: 35 | F43: 35
A44: Receivable Days | B44: 20 | C44: 25 | D44: 28 | E44: 28 | F44: 28
A45: Payable Days | B45: 25 | C45: 25 | D45: 25 | E45: 25 | F45: 25
A47: Below EBITDA (₹ Cr)
A48: Depreciation & Amortization | B48: 0.05 | C48: 0.15 | D48: 0.35 | E48: 0.6 | F48: 0.85
...

Sheet Revenue Build-up
A1: RUBAN — Revenue Build-up (₹ Cr)
B2: Year 1 | C2: Year 2 | D2: Year 3 | E2: Year 4 | F2: Year 5 | G2: CAGR
A3: Channel: Website
A4: New Customers | B4: 1800 | C4: 4500 | D4: 10500 | E4: 15400 | F4: 21600
A5: Active Customers | B5: 1800 | C5: 5500 | D5: 14000 | E5: 25200 | F5: 39600
A6: Orders/Customer/Year | B6: 1.8 | C6: 2 | D6: 2.2 | E6: 2.4 | F6: 2.5
A7: AOV (₹) | B7: 3000 | C7: 3300 | D7: 3600 | E7: 3800 | F7: 4000
A8: GMV (₹ Cr) | B8: 1.3 | C8: 3.7 | D8: 9.6 | E8: 18.4 | F8: 29.7
A9: Return Rate | B9: 0.08 | C9: 0.08 | D9: 0.07 | E9: 0.07 | F9: 0.06
A10: Net Revenue (₹ Cr) | B10: 1.2 | C10: 3.4 | D10: 8.8 | E10: 16.8 | F10: 27.2 | G10: =(F10/B10)^(1/4)-1
A12: Channel: Retail
A13: New Customers | B13: 0 | C13: 2000 | D13: 6000 | E13: 14000 | F13: 21600
A14: Active Customers | B14: 0 | C14: 2000 | D14: 7000 | E14: 18000 | F14: 33600
A15: Orders/Customer/Year | B15: 0 | C15: 1.5 | D15: 1.8 | E15: 2 | F15: 2.2
A16: AOV (₹) | B16: 0 | C16: 3800 | D16: 4200 | E16: 4500 | F16: 4800
A17: GMV (₹ Cr) | B17: 0 | C17: 1.8 | D17: 7.1 | E17: 18 | F17: 34.5
A18: Return Rate | B18: 0 | C18: 0.03 | D18: 0.03 | E18: 0.03 | F18: 0.03
A19: Net Revenue (₹ Cr) | B19: 0 | C19: 1.7 | D19: 6.6 | E19: 16.8 | F19: 32.3
A21: Channel: Marketplace
A22: New Customers | B22: 1400 | C22: 4200 | D22: 11000 | E22: 19800 | F22: 28800
A23: Active Customers | B23: 1400 | C23: 5000 | D23: 14000 | E23: 28800 | F23: 46800
A24: Orders/Customer/Year | B24: 1.5 | C24: 1.8 | D24: 2 | E24: 2.2 | F24: 2.3
A25: AOV (₹) | B25: 2500 | C25: 2800 | D25: 3000 | E25: 3200 | F25: 3400
A26: GMV (₹ Cr) | B26: 1.35 | C26: 3.8 | D26: 7.4 | E26: 16.1 | F26: 28.5
A27: Return Rate | B27: 0.1 | C27: 0.1 | D27: 0.09 | E27: 0.09 | F27: 0.08
A28: Net Revenue (₹ Cr) | B28: 1.2 | C28: 3.4 | D28: 6.6 | E28: 14.4 | F28: 25.5 | G28: =(F28/B28)^(1/4)-1
A30: Consolidated
A31: Total Customers | B31: =SUM(B5,B14,B23) | C31: =SUM(C5,C14,C23) | D31: =SUM(D5,D14,D23) | E31: =SUM(E5,E14,E23) | F31: =SUM(F5,F14,F23)
A32: Total GMV (₹ Cr) | B32: =SUM(B8,B17,B26) | C32: =SUM(C8,C17,C26) | D32: =SUM(D8,D17,D26) | E32: =SUM(E8,E17,E26) | F32: =SUM(F8,F17,F26)
A33: Total Net Revenue (₹ Cr) | B33: =B10+B19+B28 | C33: =C10+C19+C28 | D33: =D10+D19+D28 | E33: =E10+E19+E28 | F33: =F10+F19+F28 | G33: =(F33/B33)^(1/4)-1
A35: YoY Revenue Growth % | C35: =(C33-B33)/B33 | D35: =(D33-C33)/C33 | E35: =(E33-D33)/D33 | F35: =(F33-E33)/E33
A37: Year 1 — Monthly Detail (₹ Cr)
A38: Month | B38: Apr'24 | C38: May'24 | D38: Jun'24 | E38: Jul'24 | F38: Aug'24 | G38: Sep'24
A39: Net Revenue | B39: 0.08 | C39: 0.1 | D39: 0.12 | E39: 0.15 | F39: 0.18 | G39: 0.2
A41: Month | B41: Oct'24 | C41: Nov'24 | D41: Dec'24 | E41: Jan'25 | F41: Feb'25 | G41: Mar'25
A42: Net Revenue | B42: 0.22 | C42: 0.24 | D42: 0.26 | E42: 0.28 | F42: 0.28 | G42: 0.29

Sheet P&L
A1: RUBAN — Profit & Loss Statement (₹ Cr)
B2: Year 1 | C2: Year 2 | D2: Year 3 | E2: Year 4 | F2: Year 5
A3: Revenue
A4: Website | B4: 1.2 | C4: 3.4 | D4: 8.8 | E4: 16.8 | F4: 27.2
A5: Retail | B5: 0 | C5: 1.7 | D5: 6.6 | E5: 16.8 | F5: 32.3
A6: Marketplace | B6: 1.2 | C6: 3.4 | D6: 6.6 | E6: 14.4 | F6: 25.5
A7: Net Revenue | B7: =SUM(B4:B6) | C7: =SUM(C4:C6) | D7: =SUM(D4:D6) | E7: =SUM(E4:E6) | F7: =SUM(F4:F6)
A8: YoY Growth % | C8: =(C7-B7)/B7 | D8: =(D7-C7)/C7 | E8: =(E7-D7)/D7 | F8: =(F7-E7)/E7
A10: Cost of Goods Sold
A11: Website | B11: 0.58 | C11: 1.56 | D11: 3.87 | E11: 7.22 | F11: 11.42
A12: Retail | B12: 0 | C12: 0.85 | D12: 3.1 | E12: 7.56 | F12: 13.89
A13: Marketplace | B13: 0.58 | C13: 1.56 | D13: 2.9 | E13: 6.19 | F13: 10.71
A14: Total COGS | B14: =SUM(B11:B13) | C14: =SUM(C11:C13) | D14: =SUM(D11:D13) | E14: =SUM(E11:E13) | F14: =SUM(F11:F13)
A16: Gross Profit
A17: Gross Profit | B17: =B7-B14 | C17: =C7-C14 | D17: =D7-D14 | E17: =E7-E14 | F17: =F7-F14
A18: Gross Margin % | B18: =B17/B7 | C18: =C17/C7 | D18: =D17/D7 | E18: =E17/E7 | F18: =F17/F7
A20: Operating Expenses
A21: Marketing & Advertising | B21: 0.96 | C21: 2.13 | D21: 3.52 | E21: 5.28 | F21: 7.65
A22: Employee Costs | B22: 0.55 | C22: 1.2 | D22: 2.2 | E22: 3.84 | F22: 5.95
A23: Technology & Platform | B23: 0.24 | C23: 0.43 | D23: 0.66 | E23: 0.96 | F23: 1.28
A24: Rent & Utilities | B24: 0 | C24: 0.36 | D24: 0.88 | E24: 1.44 | F24: 1.87
A25: Logistics & Fulfillment | B25: 0.19 | C25: 0.6 | D25: 1.32 | E25: 2.4 | F25: 3.83
A26: Other G&A | B26: 0.14 | C26: 0.34 | D26: 0.66 | E26: 0.96 | F26: 1.19
A27: Total OPEX | B27: =SUM(B21:B26) | C27: =SUM(C21:C26) | D27: =SUM(D21:D26) | E27: =SUM(E21:E26) | F27: =SUM(F21:F26)
A28: OPEX as % of Revenue | B28: =B27/B7 | C28: =C27/C7 | D28: =D27/D7 | E28: =E27/E7 | F28: =F27/F7
A30: EBITDA
A31: EBITDA | B31: =B17-B27 | C31: =C17-C27 | D31: =D17-D27 | E31: =E17-E27 | F31: =F17-F27
A32: EBITDA Margin % | B32: =B31/B7 | C32: =C31/C7 | D32: =D31/D7 | E32: =E31/E7 | F32: =F31/F7
A34: Below EBITDA
A35: Depreciation & Amortization | B35: 0.05 | C35: 0.15 | D35: 0.35 | E35: 0.6 | F35: 0.85
A36: EBIT | B36: =B31-B35 | C36: =C31-C35 | D36: =D31-D35 | E36: =E31-E35 | F36: =F31-F35
A37: Interest Expense | B37: 0 | C37: 0.05 | D37: 0.08 | E37: 0.06 | F37: 0.03
A38: Profit Before Tax (PBT) | B38: =B36-B37 | C38: =C36-C37 | D38: =D36-D37 | E38: =E36-E37 | F38: =F36-F37
A39: Tax Provision | B39: 0 | C39: 0 | D39: 0 | E39: 0.72 | F39: 2.28
A40: Net Income (PAT) | B40: =B38-B39 | C40: =C38-C39 | D40: =D38-D39 | E40: =E38-E39 | F40: =F38-F39
A41: Net Margin % | B41: =B40/B7 | C41: =C40/C7 | D41: =D40/D7 | E41: =E40/E7 | F41: =F40/F7

Sheet Balance Sheet
A1: RUBAN — Balance Sheet (₹ Cr)
B2: Year 1 | C2: Year 2 | D2: Year 3 | E2: Year 4 | F2: Year 5
A3: Assets
A4: Cash & Equivalents | B4: 1.5 | C4: 9.8 | D4: 7.2 | E4: 41.5 | F4: 35.8
A5: Inventory | B5: 0.3 | C5: 0.85 | D5: 2.2 | E5: 4.8 | F5: 8.5
A6: Accounts Receivable | B6: 0.2 | C6: 0.7 | D6: 1.8 | E6: 4 | F6: 7.1
A7: Fixed Assets (Net of D&A) | B7: 0.3 | C7: 1.15 | D7: 2.8 | E7: 4.2 | F7: 5.35
A8: Total Assets | B8: =SUM(B4:B7) | C8: =SUM(C4:C7) | D8: =SUM(D4:D7) | E8: =SUM(E4:E7) | F8: =SUM(F4:F7)
A10: Liabilities
A11: Accounts Payable | B11: 0.15 | C11: 0.55 | D11: 1.5 | E11: 3.2 | F11: 5.65
A12: Short-term Debt | B12: 0 | C12: 0.5 | D12: 0.5 | E12: 0 | F12: 0
A13: Long-term Debt | B13: 0 | C13: 0.5 | D13: 1 | E13: 0.5 | F13: 0
A14: Total Liabilities | B14: =SUM(B11:B13) | C14: =SUM(C11:C13) | D14: =SUM(D11:D13) | E14: =SUM(E11:E13) | F14: =SUM(F11:F13)
A16: Shareholders' Equity
A17: Share Capital (Paid-in) | B17: 3 | C17: 18 | D17: 18 | E17: 68 | F17: 68
A18: Retained Earnings | B18: =B8-B14-B17 | C18: =C8-C14-C17 | D18: =D8-D14-D17 | E18: =E8-E14-E17 | F18: =F8-F14-F17
A19: Total Equity | B19: =B17+B18 | C19: =C17+C18 | D19: =D17+D18 | E19: =E17+E18 | F19: =F17+F18
A21: Balance Check
A22: Total Liabilities + Equity | B22: =B14+B19 | C22: =C14+C19 | D22: =D14+D19 | E22: =E14+E19 | F22: =F14+F19
A23: Difference (must be 0) | B23: =B8-B22 | C23: =C8-C22 | D23: =D8-D22 | E23: =E8-E22 | F23: =F8-F22

Sheet Cash Flow
A1: RUBAN — Cash Flow Statement (₹ Cr)
B2: Year 1 | C2: Year 2 | D2: Year 3 | E2: Year 4 | F2: Year 5
A3: Cash from Operating Activities
A4: Net Income (PAT) | B4: ='P&L'!B40 | C4: ='P&L'!C40 | D4: ='P&L'!D40 | E4: ='P&L'!E40 | F4: ='P&L'!F40
A5: (+) Depreciation & Amortization | B5: ='P&L'!B35 | C5: ='P&L'!C35 | D5: ='P&L'!D35 | E5: ='P&L'!E35 | F5: ='P&L'!F35
A6: (+/-) Working Capital Changes | B6: -0.35 | C6: -0.75 | D6: -1.6 | E6: -2.9 | F6: -3.95
A7: Cash from Operations | B7: =B4+B5+B6 | C7: =C4+C5+C6 | D7: =D4+D5+D6 | E7: =E4+E5+E6 | F7: =F4+F5+F6
A9: Cash from Investing Activities
A10: Capital Expenditure | B10: -0.35 | C10: -1 | D10: -2 | E10: -2 | F10: -2
A11: Cash from Investing | B11: =B10 | C11: =C10 | D11: =D10 | E11: =E10 | F11: =F10
A13: Cash from Financing Activities
A14: Equity Raised | B14: 3 | C14: 15 | D14: 0 | E14: 50 | F14: 0
A15: Net Debt (Drawn / Repaid) | B15: 0 | C15: 1 | D15: 0.5 | E15: -1 | F15: -0.5
A16: Cash from Financing | B16: =B14+B15 | C16: =C14+C15 | D16: =D14+D15 | E16: =E14+E15 | F16: =F14+F15
A18: Summary
A19: Net Cash Flow | B19: =B7+B11+B16 | C19: =C7+C11+C16 | D19: =D7+D11+D16 | E19: =E7+E11+E16 | F19: =F7+F11+F16
A20: Opening Cash Balance | B20: 0 | C20: 1.5 | D20: 9.8 | E20: 7.2 | F20: 41.5
A21: Closing Cash Balance | B21: =B20+B19 | C21: =C20+C19 | D21: =D20+D19 | E21: =E20+E19 | F21: =F20+F19

Sheet Unit Economics
A1: RUBAN — Unit Economics
B2: Year 1 | C2: Year 2 | D2: Year 3 | E2: Year 4 | F2: Year 5
A3: Blended Metrics
A4: Customer Acquisition Cost (₹) | B4: 1200 | C4: 950 | D4: 750 | E4: 600 | F4: 480
A5: Average Order Value (₹) | B5: 2800 | C5: 3100 | D5: 3400 | E5: 3600 | F5: 3800
A6: Lifetime Value (₹) | B6: 5800 | C6: 7200 | D6: 9500 | E6: 12000 | F6: 14500
A7: LTV / CAC Ratio | B7: =B6/B4 | C7: =C6/C4 | D7: =D6/D4 | E7: =E6/E4 | F7: =F6/F4
A8: Payback Period (Months) | B8: 8 | C8: 6 | D8: 5 | E8: 4 | F8: 3
A9: Repeat Purchase Rate | B9: 0.22 | C9: 0.3 | D9: 0.38 | E9: 0.44 | F9: 0.5
A10: Blended Churn Rate | B10: 0.35 | C10: 0.3 | D10: 0.25 | E10: 0.22 | F10: 0.2
A12: Churn Rate by Channel
A13: Website | B13: 0.35 | C13: 0.3 | D13: 0.25 | E13: 0.22 | F13: 0.2
A14: Retail | B14: 0 | C14: 0.2 | D14: 0.18 | E14: 0.15 | F14: 0.12
A15: Marketplace | B15: 0.4 | C15: 0.35 | D15: 0.3 | E15: 0.26 | F15: 0.22
A17: Contribution Margin per Order (₹)
A18: Website | B18: 680 | C18: 820 | D18: 1050 | E18: 1280 | F18: 1520
A19: Retail | B19: 0 | C19: 750 | D19: 980 | E19: 1200 | F19: 1450
A20: Marketplace | B20: 420 | C20: 560 | D20: 720 | E20: 900 | F20: 1080

Sheet Fundraising
A1: RUBAN — Fundraising & Cap Table
A3: Round Details (₹ Cr)
A4: Round | B4: Timing | C4: Amount | D4: Pre-Money | E4: Post-Money | F4: Dilution
A5: Seed | B5: Y1 | C5: 3 | D5: 12 | E5: 15 | F5: 0.2
A6: Series A | B6: Y2 | C6: 15 | D6: 60 | E6: 75 | F6: 0.2
A7: Series B | B7: Y4 | C7: 50 | D7: 250 | E7: 300 | F7: 0.167
A9: Cap Table Evolution (%)
A10: Shareholder | B10: Year 1 | C10: Year 2 | D10: Year 3 | E10: Year 4 | F10: Year 5
A11: Founders | B11: 0.8 | C11: 0.64 | D11: 0.512 | E11: 0.427 | F11: 0.427
A12: ESOP | B12: 0 | C12: 0.05 | D12: 0.08 | E12: 0.08 | F12: 0.1
A13: Seed Investors | B13: 0.2 | C13: 0.16 | D13: 0.128 | E13: 0.107 | F13: 0.107
A14: Series A | B14: 0 | C14: 0.15 | D14: 0.12 | E14: 0.1 | F14: 0.1
A15: Series B | B15: 0 | C15: 0 | D15: 0 | E15: 0.167 | F15: 0.167
A16: Others | B16: 0 | C16: 0 | D16: 0.16 | E16: 0.119 | F16: 0.099
A17: Total | B17: =SUM(B11:B16) | C17: =SUM(C11:C16) | D17: =SUM(D11:D16) | E17: =SUM(E11:E16) | F17: =SUM(F11:F16)
A19: Use of Funds (₹ Cr)
A20: Category | B20: Seed | C20: Series A | D20: Series B
A21: Marketing | B21: 1 | C21: 5 | D21: 15
A22: Technology | B22: 0.8 | C22: 2.5 | D22: 8
A23: Team | B23: 0.6 | C23: 3 | D23: 10
A24: Inventory | B24: 0.4 | C24: 2.5 | D24: 10
A25: Working Capital | B25: 0.2 | C25: 2 | D25: 7
A26: Total | B26: =SUM(B21:B25) | C26: =SUM(C21:C25) | D26: =SUM(D21:D25)
A28: Investor Returns (Y5 Exit @ ₹680 Cr)
A29: Round | B29: Invested | C29: Stake@Exit | D29: Return ₹Cr | E29: MOIC | F29: IRR
A30: Seed | B30: 3 | C30: 0.107 | D30: 72.8 | E30: 24.2 | F30: 0.82
A31: Series A | B31: 15 | C31: 0.1 | D31: 68 | E31: 4.5 | F31: 0.65
A32: Series B | B32: 50 | C32: 0.167 | D32: 113.6 | E32: 2.3 | F32: 0.68
A34: Cash Runway
A35: Monthly Burn (₹ Cr) | B35: 0.15 | C35: 0.25 | D35: 0.1 | E35: 0 | F35: 0
A36: Runway (Months) | B36: 20 | C36: 39 | D36: 72 | E36: Profitable | F36: Profitable

Sheet _ChartData
A1: Year | B1: Year 1 | C1: Year 2 | D1: Year 3 | E1: Year 4 | F1: Year 5
A2: Website | B2: 1.2 | C2: 3.4 | D2: 8.8 | E2: 16.8 | F2: 27.2
A3: Retail | B3: 0 | C3: 1.7 | D3: 6.6 | E3: 16.8 | F3: 32.3
A4: Marketplace | B4: 1.2 | C4: 3.4 | D4: 6.6 | E4: 14.4 | F4: 25.5
A5: Total | B5: 2.4 | C5: 8.5 | D5: 22 | E5: 48 | F5: 85
A7: Channel | B7: Revenue Y5
A8: Website | B8: 27.2
A9: Retail | B9: 32.3
A10: Marketplace | B10: 25.5
A12: Metric | B12: Value
A13: Gross Margin | B13: 0.58
A14: EBITDA Margin | B14: 0.18
A15: Net Margin | B15: 0.287
A17: Year | B17: Year 1 | C17: Year 2 | D17: Year 3 | E17: Year 4 | F17: Year 5
A18: Website | B18: 1800 | C18: 5500 | D18: 14000 | E18: 25200 | F18: 39600
A19: Retail | B19: 0 | C19: 2000 | D19: 7000 | E19: 18000 | F19: 33600
A20: Marketplace | B20: 1400 | C20: 5000 | D20: 14000 | E20: 28800 | F20: 46800
A22: Stage | B22: Count
A23: Visitors | B23: 2400000
A24: Leads | B24: 480000
A25: Customers | B25: 120000
A26: Repeat | B26: 60000
A28: Category | B28: Amount
A29: Marketing | B29: 15
A30: Technology | B30: 8
A31: Team | B31: 10
A32: Inventory | B32: 10
A33: Working Capital | B33: 7
A35: Holder | B35: Stake %
A36: Founders | B36: 42.7
A37: ESOP | B37: 10
A38: Seed Investors | B38: 10.7
A39: Series A | B39: 10
A40: Series B | B40: 16.7
A41: Others | B41: 9.9
